Workbook

Sheet Справочники
A1: Тип оборудования | C1: Статус оборудования
A2: СИ | C2: В работе
A3: ИО | C3: В поверке
A4: ВО | C4: В ремонте
A5: Другое | C5: Списан

Sheet Настройки
A1: Параметр | B1: Значение
A2: Контрольная дата | B2: 46092
A3: Комментарий | B3: Измените B2, если хотите протестировать дедлайны на другую дату.

Sheet Главная
A1: УЧЕТ ОБОРУДОВАНИЯ И РЕМОНТОВ — DEMO v2
A4: Всего оборудования | B4: =COUNTA(Оборудование!A2:A200) | C4: В ремонте | D4: =COUNTIF(Оборудование!H2:H200,"В ремонте") | E4: Есть просрочки | F4: =COUNTIF(Ремонты!Y2:Y200,">0")
A8: СИ | B8: =COUNTIF(Оборудование!C2:C200,"СИ") | C8: ИО / ВО | D8: =COUNTIF(Оборудование!C2:C200,"ИО")+COUNTIF(Оборудование!C2:C200,"ВО") | E8: Другое | F8: =COUNTIF(Оборудование!C2:C200,"Другое")
A12: Контрольная дата | B12: =Настройки!B2
A14: Навигация
A15: Оборудование | B15: Реестр с фильтрами
A16: Ремонты | B16: Сроки и маршрут ремонта
A17: Журнал_событий | B17: Автожурнал по листу Ремонты
A18: Карточка_прибора | B18: Экран выбранного прибора
A19: Поверка_СИ | B19: Подробные сведения по СИ

Sheet Оборудование
A1: ID прибора | B1: Объект | C1: Тип | D1: Наименование | E1: Модификация | F1: Заводской номер | G1: Год выпуска | H1: Статус | I1: Где сейчас прибор | J1: Активный ремонт | K1: Рег. номер типа СИ | L1: Наименование типа СИ | M1: Обозначение типа СИ | N1: Номер свидетельства | O1: Дата поверки | P1: Поверка до | Q1: Владелец СИ | R1: Сценарий теста
A2: SI-0001 | B2: Химико-аналитическая лаборатория | C2: СИ | D2: Влагомеры нефти поточные | E2: исп. УДВН-1пм | F2: 2459 | G2: 2022 | H2: В ремонте | I2: =IFERROR(INDEX(Ремонты!$T$2:$T$200,MATCH(A2,Ремонты!$A$2:$A$200,0)),H2) | J2: =IF(COUNTIF(Ремонты!$A$2:$A$200,A2)>0,"Да","Нет") | K2: 14557-15 | L2: Влагомеры нефти поточные | M2: УДВН-1пм | N2: С-ББЮ/06-03-2026/509701256 | O2: 46087 | P2: 46451 | Q2: АО «Транснефть - Приволга» | R2: Ремонт в срок
A3: SI-0002 | B3: Химико-аналитическая лаборатория | C3: СИ | D3: Влагомеры нефти поточные | E3: исп. УДВН-1пм | F3: 2460 | G3: 2022 | H3: В ремонте | I3: =IFERROR(INDEX(Ремонты!$T$2:$T$200,MATCH(A3,Ремонты!$A$2:$A$200,0)),H3) | J3: =IF(COUNTIF(Ремонты!$A$2:$A$200,A3)>0,"Да","Нет") | K3: 14557-15 | L3: Влагомеры нефти поточные | M3: УДВН-1пм | N3: С-ББЮ/06-03-2026/509701256 | O3: 46087 | P3: 46451 | Q3: АО «Транснефть - Приволга» | R3: Ожидание получения в Ленске
A4: SI-0003 | B4: Химико-аналитическая лаборатория | C4: СИ | D4: Влагомеры нефти поточные | E4: исп. УДВН-1пм | F4: 2461 | G4: 2022 | H4: В ремонте | I4: =IFERROR(INDEX(Ремонты!$T$2:$T$200,MATCH(A4,Ремонты!$A$2:$A$200,0)),H4) | J4: =IF(COUNTIF(Ремонты!$A$2:$A$200,A4)>0,"Да","Нет") | K4: 14557-15 | L4: Влагомеры нефти поточные | M4: УДВН-1пм | N4: С-ББЮ/06-03-2026/509701256 | O4: 46087 | P4: 46451 | Q4: АО «Транснефть - Приволга» | R4: Просрочен входной контроль
A5: SI-0004 | B5: Химико-аналитическая лаборатория | C5: СИ | D5: Влагомеры нефти поточные | E5: исп. УДВН-1пм | F5: 2462 | G5: 2022 | H5: В ремонте | I5: =IFERROR(INDEX(Ремонты!$T$2:$T$200,MATCH(A5,Ремонты!$A$2:$A$200,0)),H5) | J5: =IF(COUNTIF(Ремонты!$A$2:$A$200,A5)>0,"Да","Нет") | K5: 14557-15 | L5: Влагомеры нефти поточные | M5: УДВН-1пм | N5: С-ББЮ/06-03-2026/509701256 | O5: 46087 | P5: 46451 | Q5: АО «Транснефть - Приволга» | R5: Просрочена оплата
A6: SI-0005 | B6: Химико-аналитическая лаборатория | C6: СИ | D6: Влагомеры нефти поточные | E6: исп. УДВН-1пм | F6: 2463 | G6: 2022 | H6: В работе | I6: =IFERROR(INDEX(Ремонты!$T$2:$T$200,MATCH(A6,Ремонты!$A$2:$A$200,0)),H6) | J6: =IF(COUNTIF(Ремонты!$A$2:$A$200,A6)>0,"Да","Нет") | K6: 14557-15 | L6: Влагомеры нефти поточные | M6: УДВН-1пм | N6: С-ББЮ/06-03-2026/509701256 | O6: 46087 | P6: 46451 | Q6: АО «Транснефть - Приволга» | R6: Ремонт завершен
A7: VO-0001 | B7: Химико-аналитическая лаборатория | C7: ВО | D7: Электроплитка для лабораторного оборудования | E7: ЭПЛ-220 | F7: VO7781 | G7: 2024 | H7: В работе | I7: =IFERROR(INDEX(Ремонты!$T$2:$T$200,MATCH(A7,Ремонты!$A$2:$A$200,0)),H7) | J7: =IF(COUNTIF(Ремонты!$A$2:$A$200,A7)>0,"Да","Нет") | R7: ВО — пример
A8: IO-0001 | B8: Химико-аналитическая лаборатория | C8: ИО | D8: Центрифуга лабораторная | E8: ЦЛ-80 | F8: IO5532 | G8: 2023 | H8: В ремонте | I8: =IFERROR(INDEX(Ремонты!$T$2:$T$200,MATCH(A8,Ремонты!$A$2:$A$200,0)),H8) | J8: =IF(COUNTIF(Ремонты!$A$2:$A$200,A8)>0,"Да","Нет") | R8: ИО — пример
A9: OT-0001 | B9: Химико-аналитическая лаборатория | C9: Другое | D9: Блок питания | E9: BP-24/5 | F9: OT2045 | G9: 2025 | H9: В работе | I9: =IFERROR(INDEX(Ремонты!$T$2:$T$200,MATCH(A9,Ремонты!$A$2:$A$200,0)),H9) | J9: =IF(COUNTIF(Ремонты!$A$2:$A$200,A9)>0,"Да","Нет") | R9: Другое — пример
I10: =IFERROR(INDEX(Ремонты!$T$2:$T$200,MATCH(A10,Ремонты!$A$2:$A$200,0)),H10) | J10: =IF(COUNTIF(Ремонты!$A$2:$A$200,A10)>0,"Да","Нет")
I11: =IFERROR(INDEX(Ремонты!$T$2:$T$200,MATCH(A11,Ремонты!$A$2:$A$200,0)),H11) | J11: =IF(COUNTIF(Ремонты!$A$2:$A$200,A11)>0,"Да","Нет")
I12: =IFERROR(INDEX(Ремонты!$T$2:$T$200,MATCH(A12,Ремонты!$A$2:$A$200,0)),H12) | J12: =IF(COUNTIF(Ремонты!$A$2:$A$200,A12)>0,"Да","Нет")
I13: =IFERROR(INDEX(Ремонты!$T$2:$T$200,MATCH(A13,Ремонты!$A$2:$A$200,0)),H13) | J13: =IF(COUNTIF(Ремонты!$A$2:$A$200,A13)>0,"Да","Нет")
I14: =IFERROR(INDEX(Ремонты!$T$2:$T$200,MATCH(A14,Ремонты!$A$2:$A$200,0)),H14) | J14: =IF(COUNTIF(Ремонты!$A$2:$A$200,A14)>0,"Да","Нет")
I15: =IFERROR(INDEX(Ремонты!$T$2:$T$200,MATCH(A15,Ремонты!$A$2:$A$200,0)),H15) | J15: =IF(COUNTIF(Ремонты!$A$2:$A$200,A15)>0,"Да","Нет")
I16: =IFERROR(INDEX(Ремонты!$T$2:$T$200,MATCH(A16,Ремонты!$A$2:$A$200,0)),H16) | J16: =IF(COUNTIF(Ремонты!$A$2:$A$200,A16)>0,"Да","Нет")
I17: =IFERROR(INDEX(Ремонты!$T$2:$T$200,MATCH(A17,Ремонты!$A$2:$A$200,0)),H17) | J17: =IF(COUNTIF(Ремонты!$A$2:$A$200,A17)>0,"Да","Нет")
I18: =IFERROR(INDEX(Ремонты!$T$2:$T$200,MATCH(A18,Ремонты!$A$2:$A$200,0)),H18) | J18: =IF(COUNTIF(Ремонты!$A$2:$A$200,A18)>0,"Да","Нет")
I19: =IFERROR(INDEX(Ремонты!$T$2:$T$200,MATCH(A19,Ремонты!$A$2:$A$200,0)),H19) | J19: =IF(COUNTIF(Ремонты!$A$2:$A$200,A19)>0,"Да","Нет")
I20: =IFERROR(INDEX(Ремонты!$T$2:$T$200,MATCH(A20,Ремонты!$A$2:$A$200,0)),H20) | J20: =IF(COUNTIF(Ремонты!$A$2:$A$200,A20)>0,"Да","Нет")
I21: =IFERROR(INDEX(Ремонты!$T$2:$T$200,MATCH(A21,Ремонты!$A$2:$A$200,0)),H21) | J21: =IF(COUNTIF(Ремонты!$A$2:$A$200,A21)>0,"Да","Нет")
... I200: =IFERROR(INDEX(Ремонты!$T$2:$T$200,MATCH(A200,Ремонты!$A$2:$A$200,0)),H200) | J200: =IF(COUNTIF(Ремонты!$A$2:$A$200,A200)>0,"Да","Нет")

Sheet Поверка_СИ
A1: ID прибора | B1: Регистрационный номер типа СИ | C1: Обозначение типа СИ | D1: Наименование типа СИ | E1: Заводской номер СИ | F1: Модификация СИ | G1: Организация-поверитель | H1: Шифр знака поверки | I1: Владелец СИ | J1: Тип поверки | K1: Дата поверки СИ | L1: Поверка действительна до | M1: Документ поверки | N1: СИ пригодно | O1: Номер свидетельства | P1: Знак поверки в паспорте | Q1: Знак поверки на СИ | R1: Средство поверки / эталон
A2: SI-0001 | B2: 14557-15 | C2: УДВН-1пм | D2: Влагомеры нефти поточные | E2: 2459 | F2: исп. УДВН-1пм | G2: АО "ТРАНСНЕФТЬ-АВТОМАТИЗАЦИЯ И МЕТРОЛОГИЯ" | H2: ББЮ | I2: АО «Транснефть - Приволга» | J2: Периодическая | K2: 46087 | L2: 46451 | M2: МП 0309-6-2015 «Инструкция. ГСИ. Влагомеры нефти поточные УДВН-1пм. Методика поверки» | N2: Да | O2: С-ББЮ/06-03-2026/509701256 | P2: Нет | Q2: Нет | R2: 59937-20; Влагомеры эталонные товарной нефти поточные; УДВН-1эп; Эталон 2-го разряда; ГОСТ 8.614-2013
A3: SI-0002 | B3: 14557-15 | C3: УДВН-1пм | D3: Влагомеры нефти поточные | E3: 2460 | F3: исп. УДВН-1пм | G3: АО "ТРАНСНЕФТЬ-АВТОМАТИЗАЦИЯ И МЕТРОЛОГИЯ" | H3: ББЮ | I3: АО «Транснефть - Приволга» | J3: Периодическая | K3: 46087 | L3: 46451 | M3: МП 0309-6-2015 «Инструкция. ГСИ. Влагомеры нефти поточные УДВН-1пм. Методика поверки» | N3: Да | O3: С-ББЮ/06-03-2026/509701256 | P3: Нет | Q3: Нет | R3: 59937-20; Влагомеры эталонные товарной нефти поточные; УДВН-1эп; Эталон 2-го разряда; ГОСТ 8.614-2013
A4: SI-0003 | B4: 14557-15 | C4: УДВН-1пм | D4: Влагомеры нефти поточные | E4: 2461 | F4: исп. УДВН-1пм | G4: АО "ТРАНСНЕФТЬ-АВТОМАТИЗАЦИЯ И МЕТРОЛОГИЯ" | H4: ББЮ | I4: АО «Транснефть - Приволга» | J4: Периодическая | K4: 46087 | L4: 46451 | M4: МП 0309-6-2015 «Инструкция. ГСИ. Влагомеры нефти поточные УДВН-1пм. Методика поверки» | N4: Да | O4: С-ББЮ/06-03-2026/509701256 | P4: Нет | Q4: Нет | R4: 59937-20; Влагомеры эталонные товарной нефти поточные; УДВН-1эп; Эталон 2-го разряда; ГОСТ 8.614-2013
A5: SI-0004 | B5: 14557-15 | C5: УДВН-1пм | D5: Влагомеры нефти поточные | E5: 2462 | F5: исп. УДВН-1пм | G5: АО "ТРАНСНЕФТЬ-АВТОМАТИЗАЦИЯ И МЕТРОЛОГИЯ" | H5: ББЮ | I5: АО «Транснефть - Приволга» | J5: Периодическая | K5: 46087 | L5: 46451 | M5: МП 0309-6-2015 «Инструкция. ГСИ. Влагомеры нефти поточные УДВН-1пм. Методика поверки» | N5: Да | O5: С-ББЮ/06-03-2026/509701256 | P5: Нет | Q5: Нет | R5: 59937-20; Влагомеры эталонные товарной нефти поточные; УДВН-1эп; Эталон 2-го разряда; ГОСТ 8.614-2013
A6: SI-0005 | B6: 14557-15 | C6: УДВН-1пм | D6: Влагомеры нефти поточные | E6: 2463 | F6: исп. УДВН-1пм | G6: АО "ТРАНСНЕФТЬ-АВТОМАТИЗАЦИЯ И МЕТРОЛОГИЯ" | H6: ББЮ | I6: АО «Транснефть - Приволга» | J6: Периодическая | K6: 46087 | L6: 46451 | M6: МП 0309-6-2015 «Инструкция. ГСИ. Влагомеры нефти поточные УДВН-1пм. Методика поверки» | N6: Да | O6: С-ББЮ/06-03-2026/509701256 | P6: Нет | Q6: Нет | R6: 59937-20; Влагомеры эталонные товарной нефти поточные; УДВН-1эп; Эталон 2-го разряда; ГОСТ 8.614-2013

Sheet Ремонты
A1: ID прибора | B1: Сценарий | C1: Объект | D1: Тип | E1: Наименование | F1: Статус из реестра | G1: Дата отправки в ремонт | H1: Дедлайн ремонта (100) | I1: Дата отправки из ремонта | J1: Дата отправки из Иркутска | K1: Дата прибытия в Ленск | L1: Дедлайн регистрации (5) | M1: Фактическое получение | N1: Начало контроля | O1: Дедлайн контроля (40) | P1: Дата входного контроля | Q1: Начало оплаты | R1: Дедлайн оплаты (70) | S1: Дата оплаты | T1: Где сейчас прибор | U1: Просрочка ремонта | V1: Просрочка регистрации | W1: Просрочка контроля | X1: Просрочка оплаты | Y1: Макс. просрочка
A2: SI-0001 | B2: Ремонт в срок | C2: =IFERROR(INDEX(Оборудование!$B$2:$B$200,MATCH(A2,Оборудование!$A$2:$A$200,0)),"") | D2: =IFERROR(INDEX(Оборудование!$C$2:$C$200,MATCH(A2,Оборудование!$A$2:$A$200,0)),"") | E2: =IFERROR(INDEX(Оборудование!$D$2:$D$200,MATCH(A2,Оборудование!$A$2:$A$200,0)),"") | F2: =IFERROR(INDEX(Оборудование!$H$2:$H$200,MATCH(A2,Оборудование!$A$2:$A$200,0)),"") | G2: 46054 | H2: =IF(G2="","",G2+100) | L2: =IF(K2="","",K2+5) | N2: =IF(M2<>"",M2,IF(L2="","",L2)) | O2: =IF(N2="","",N2+40) | Q2: =IF(P2<>"",P2,IF(O2="","",O2)) | R2: =IF(Q2="","",Q2+70) | T2: =IF(G2="","",IF(S2<>"","Завершено",IF(P2<>"","Ожидание оплаты",IF(M2<>"","Входной контроль",IF(K2<>"","Ожидание получения в Ленске",IF(I2<>"","В пути Иркутск → Ленск","Ремонт у подрядчика")))))) | U2: =IF(H2="","",MAX(0,IF(I2<>"",I2,Настройки!$B$2)-H2)) | V2: =IF(L2="","",MAX(0,IF(M2<>"",M2,Настройки!$B$2)-L2)) | W2: =IF(O2="","",MAX(0,IF(P2<>"",P2,Настройки!$B$2)-O2)) | X2: =IF(R2="","",MAX(0,IF(S2<>"",S2,Настройки!$B$2)-R2)) | Y2: =MAX(U2:X2)
A3: SI-0002 | B3: Ожидание получения в Ленске | C3: =IFERROR(INDEX(Оборудование!$B$2:$B$200,MATCH(A3,Оборудование!$A$2:$A$200,0)),"") | D3: =IFERROR(INDEX(Оборудование!$C$2:$C$200,MATCH(A3,Оборудование!$A$2:$A$200,0)),"") | E3: =IFERROR(INDEX(Оборудование!$D$2:$D$200,MATCH(A3,Оборудование!$A$2:$A$200,0)),"") | F3: =IFERROR(INDEX(Оборудование!$H$2:$H$200,MATCH(A3,Оборудование!$A$2:$A$200,0)),"") | G3: 45971 | H3: =IF(G3="","",G3+100) | I3: 46068 | J3: 46071 | K3: 46085 | L3: =IF(K3="","",K3+5) | N3: =IF(M3<>"",M3,IF(L3="","",L3)) | O3: =IF(N3="","",N3+40) | Q3: =IF(P3<>"",P3,IF(O3="","",O3)) | R3: =IF(Q3="","",Q3+70) | T3: =IF(G3="","",IF(S3<>"","Завершено",IF(P3<>"","Ожидание оплаты",IF(M3<>"","Входной контроль",IF(K3<>"","Ожидание получения в Ленске",IF(I3<>"","В пути Иркутск → Ленск","Ремонт у подрядчика")))))) | U3: =IF(H3="","",MAX(0,IF(I3<>"",I3,Настройки!$B$2)-H3)) | V3: =IF(L3="","",MAX(0,IF(M3<>"",M3,Настройки!$B$2)-L3)) | W3: =IF(O3="","",MAX(0,IF(P3<>"",P3,Настройки!$B$2)-O3)) | X3: =IF(R3="","",MAX(0,IF(S3<>"",S3,Настройки!$B$2)-R3)) | Y3: =MAX(U3:X3)
A4: SI-0003 | B4: Просрочен входной контроль | C4: =IFERROR(INDEX(Оборудование!$B$2:$B$200,MATCH(A4,Оборудование!$A$2:$A$200,0)),"") | D4: =IFERROR(INDEX(Оборудование!$C$2:$C$200,MATCH(A4,Оборудование!$A$2:$A$200,0)),"") | E4: =IFERROR(INDEX(Оборудование!$D$2:$D$200,MATCH(A4,Оборудование!$A$2:$A$200,0)),"") | F4: =IFERROR(INDEX(Оборудование!$H$2:$H$200,MATCH(A4,Оборудование!$A$2:$A$200,0)),"") | G4: 45931 | H4: =IF(G4="","",G4+100) | I4: 46027 | J4: 46030 | K4: 46032 | L4: =IF(K4="","",K4+5) | M4: 46034 | N4: =IF(M4<>"",M4,IF(L4="","",L4)) | O4: =IF(N4="","",N4+40) | Q4: =IF(P4<>"",P4,IF(O4="","",O4)) | R4: =IF(Q4="","",Q4+70) | T4: =IF(G4="","",IF(S4<>"","Завершено",IF(P4<>"","Ожидание оплаты",IF(M4<>"","Входной контроль",IF(K4<>"","Ожидание получения в Ленске",IF(I4<>"","В пути Иркутск → Ленск","Ремонт у подрядчика")))))) | U4: =IF(H4="","",MAX(0,IF(I4<>"",I4,Настройки!$B$2)-H4)) | V4: =IF(L4="","",MAX(0,IF(M4<>"",M4,Настройки!$B$2)-L4)) | W4: =IF(O4="","",MAX(0,IF(P4<>"",P4,Настройки!$B$2)-O4)) | X4: =IF(R4="","",MAX(0,IF(S4<>"",S4,Настройки!$B$2)-R4)) | Y4: =MAX(U4:X4)
A5: SI-0004 | B5: Просрочена оплата | C5: =IFERROR(INDEX(Оборудование!$B$2:$B$200,MATCH(A5,Оборудование!$A$2:$A$200,0)),"") | D5: =IFERROR(INDEX(Оборудование!$C$2:$C$200,MATCH(A5,Оборудование!$A$2:$A$200,0)),"") | E5: =IFERROR(INDEX(Оборудование!$D$2:$D$200,MATCH(A5,Оборудование!$A$2:$A$200,0)),"") | F5: =IFERROR(INDEX(Оборудование!$H$2:$H$200,MATCH(A5,Оборудование!$A$2:$A$200,0)),"") | G5: 45839 | H5: =IF(G5="","",G5+100) | I5: 45935 | J5: 45937 | K5: 45940 | L5: =IF(K5="","",K5+5) | M5: 45942 | N5: =IF(M5<>"",M5,IF(L5="","",L5)) | O5: =IF(N5="","",N5+40) | P5: 45981 | Q5: =IF(P5<>"",P5,IF(O5="","",O5)) | R5: =IF(Q5="","",Q5+70) | T5: =IF(G5="","",IF(S5<>"","Завершено",IF(P5<>"","Ожидание оплаты",IF(M5<>"","Входной контроль",IF(K5<>"","Ожидание получения в Ленске",IF(I5<>"","В пути Иркутск → Ленск","Ремонт у подрядчика")))))) | U5: =IF(H5="","",MAX(0,IF(I5<>"",I5,Настройки!$B$2)-H5)) | V5: =IF(L5="","",MAX(0,IF(M5<>"",M5,Настройки!$B$2)-L5)) | W5: =IF(O5="","",MAX(0,IF(P5<>"",P5,Настройки!$B$2)-O5)) | X5: =IF(R5="","",MAX(0,IF(S5<>"",S5,Настройки!$B$2)-R5)) | Y5: =MAX(U5:X5)
A6: SI-0005 | B6: Ремонт завершен | C6: =IFERROR(INDEX(Оборудование!$B$2:$B$200,MATCH(A6,Оборудование!$A$2:$A$200,0)),"") | D6: =IFERROR(INDEX(Оборудование!$C$2:$C$200,MATCH(A6,Оборудование!$A$2:$A$200,0)),"") | E6: =IFERROR(INDEX(Оборудование!$D$2:$D$200,MATCH(A6,Оборудование!$A$2:$A$200,0)),"") | F6: =IFERROR(INDEX(Оборудование!$H$2:$H$200,MATCH(A6,Оборудование!$A$2:$A$200,0)),"") | G6: 45992 | H6: =IF(G6="","",G6+100) | I6: 46037 | J6: 46039 | K6: 46043 | L6: =IF(K6="","",K6+5) | M6: 46044 | N6: =IF(M6<>"",M6,IF(L6="","",L6)) | O6: =IF(N6="","",N6+40) | P6: 46058 | Q6: =IF(P6<>"",P6,IF(O6="","",O6)) | R6: =IF(Q6="","",Q6+70) | S6: 46073 | T6: =IF(G6="","",IF(S6<>"","Завершено",IF(P6<>"","Ожидание оплаты",IF(M6<>"","Входной контроль",IF(K6<>"","Ожидание получения в Ленске",IF(I6<>"","В пути Иркутск → Ленск","Ремонт у подрядчика")))))) | U6: =IF(H6="","",MAX(0,IF(I6<>"",I6,Настройки!$B$2)-H6)) | V6: =IF(L6="","",MAX(0,IF(M6<>"",M6,Настройки!$B$2)-L6)) | W6: =IF(O6="","",MAX(0,IF(P6<>"",P6,Настройки!$B$2)-O6)) | X6: =IF(R6="","",MAX(0,IF(S6<>"",S6,Настройки!$B$2)-R6)) | Y6: =MAX(U6:X6)
A7: IO-0001 | B7: ИО — пример | C7: =IFERROR(INDEX(Оборудование!$B$2:$B$200,MATCH(A7,Оборудование!$A$2:$A$200,0)),"") | D7: =IFERROR(INDEX(Оборудование!$C$2:$C$200,MATCH(A7,Оборудование!$A$2:$A$200,0)),"") | E7: =IFERROR(INDEX(Оборудование!$D$2:$D$200,MATCH(A7,Оборудование!$A$2:$A$200,0)),"") | F7: =IFERROR(INDEX(Оборудование!$H$2:$H$200,MATCH(A7,Оборудование!$A$2:$A$200,0)),"") | G7: 46042 | H7: =IF(G7="","",G7+100) | I7: 46071 | J7: 46073 | K7: 46078 | L7: =IF(K7="","",K7+5) | M7: 46079 | N7: =IF(M7<>"",M7,IF(L7="","",L7)) | O7: =IF(N7="","",N7+40) | Q7: =IF(P7<>"",P7,IF(O7="","",O7)) | R7: =IF(Q7="","",Q7+70) | T7: =IF(G7="","",IF(S7<>"","Завершено",IF(P7<>"","Ожидание оплаты",IF(M7<>"","Входной контроль",IF(K7<>"","Ожидание получения в Ленске",IF(I7<>"","В пути Иркутск → Ленск","Ремонт у подрядчика")))))) | U7: =IF(H7="","",MAX(0,IF(I7<>"",I7,Настройки!$B$2)-H7)) | V7: =IF(L7="","",MAX(0,IF(M7<>"",M7,Настройки!$B$2)-L7)) | W7: =IF(O7="","",MAX(0,IF(P7<>"",P7,Настройки!$B$2)-O7)) | X7: =IF(R7="","",MAX(0,IF(S7<>"",S7,Настройки!$B$2)-R7)) | Y7: =MAX(U7:X7)
C8: =IFERROR(INDEX(Оборудование!$B$2:$B$200,MATCH(A8,Оборудование!$A$2:$A$200,0)),"") | D8: =IFERROR(INDEX(Оборудование!$C$2:$C$200,MATCH(A8,Оборудование!$A$2:$A$200,0)),"") | E8: =IFERROR(INDEX(Оборудование!$D$2:$D$200,MATCH(A8,Оборудование!$A$2:$A$200,0)),"") | F8: =IFERROR(INDEX(Оборудование!$H$2:$H$200,MATCH(A8,Оборудование!$A$2:$A$200,0)),"") | H8: =IF(G8="","",G8+100) | L8: =IF(K8="","",K8+5) | N8: =IF(M8<>"",M8,IF(L8="","",L8)) | O8: =IF(N8="","",N8+40) | Q8: =IF(P8<>"",P8,IF(O8="","",O8)) | R8: =IF(Q8="","",Q8+70) | T8: =IF(G8="","",IF(S8<>"","Завершено",IF(P8<>"","Ожидание оплаты",IF(M8<>"","Входной контроль",IF(K8<>"","Ожидание получения в Ленске",IF(I8<>"","В пути Иркутск → Ленск","Ремонт у подрядчика")))))) | U8: =IF(H8="","",MAX(0,IF(I8<>"",I8,Настройки!$B$2)-H8)) | V8: =IF(L8="","",MAX(0,IF(M8<>"",M8,Настройки!$B$2)-L8)) | W8: =IF(O8="","",MAX(0,IF(P8<>"",P8,Настройки!$B$2)-O8)) | X8: =IF(R8="","",MAX(0,IF(S8<>"",S8,Настройки!$B$2)-R8)) | Y8: =MAX(U8:X8)
C9: =IFERROR(INDEX(Оборудование!$B$2:$B$200,MATCH(A9,Оборудование!$A$2:$A$200,0)),"") | D9: =IFERROR(INDEX(Оборудование!$C$2:$C$200,MATCH(A9,Оборудование!$A$2:$A$200,0)),"") | E9: =IFERROR(INDEX(Оборудование!$D$2:$D$200,MATCH(A9,Оборудование!$A$2:$A$200,0)),"") | F9: =IFERROR(INDEX(Оборудование!$H$2:$H$200,MATCH(A9,Оборудование!$A$2:$A$200,0)),"") | H9: =IF(G9="","",G9+100) | L9: =IF(K9="","",K9+5) | N9: =IF(M9<>"",M9,IF(L9="","",L9)) | O9: =IF(N9="","",N9+40) | Q9: =IF(P9<>"",P9,IF(O9="","",O9)) | R9: =IF(Q9="","",Q9+70) | T9: =IF(G9="","",IF(S9<>"","Завершено",IF(P9<>"","Ожидание оплаты",IF(M9<>"","Входной контроль",IF(K9<>"","Ожидание получения в Ленске",IF(I9<>"","В пути Иркутск → Ленск","Ремонт у подрядчика")))))) | U9: =IF(H9="","",MAX(0,IF(I9<>"",I9,Настройки!$B$2)-H9)) | V9: =IF(L9="","",MAX(0,IF(M9<>"",M9,Настройки!$B$2)-L9)) | W9: =IF(O9="","",MAX(0,IF(P9<>"",P9,Настройки!$B$2)-O9)) | X9: =IF(R9="","",MAX(0,IF(S9<>"",S9,Настройки!$B$2)-R9)) | Y9: =MAX(U9:X9)
C10: =IFERROR(INDEX(Оборудование!$B$2:$B$200,MATCH(A10,Оборудование!$A$2:$A$200,0)),"") | D10: =IFERROR(INDEX(Оборудование!$C$2:$C$200,MATCH(A10,Оборудование!$A$2:$A$200,0)),"") | E10: =IFERROR(INDEX(Оборудование!$D$2:$D$200,MATCH(A10,Оборудование!$A$2:$A$200,0)),"") | F10: =IFERROR(INDEX(Оборудование!$H$2:$H$200,MATCH(A10,Оборудование!$A$2:$A$200,0)),"") | H10: =IF(G10="","",G10+100) | L10: =IF(K10="","",K10+5) | N10: =IF(M10<>"",M10,IF(L10="","",L10)) | O10: =IF(N10="","",N10+40) | Q10: =IF(P10<>"",P10,IF(O10="","",O10)) | R10: =IF(Q10="","",Q10+70) | T10: =IF(G10="","",IF(S10<>"","Завершено",IF(P10<>"","Ожидание оплаты",IF(M10<>"","Входной контроль",IF(K10<>"","Ожидание получения в Ленске",IF(I10<>"","В пути Иркутск → Ленск","Ремонт у подрядчика")))))) | U10: =IF(H10="","",MAX(0,IF(I10<>"",I10,Настройки!$B$2)-H10)) | V10: =IF(L10="","",MAX(0,IF(M10<>"",M10,Настройки!$B$2)-L10)) | W10: =IF(O10="","",MAX(0,IF(P10<>"",P10,Настройки!$B$2)-O10)) | X10: =IF(R10="","",MAX(0,IF(S10<>"",S10,Настройки!$B$2)-R10)) | Y10: =MAX(U10:X10)
C11: =IFERROR(INDEX(Оборудование!$B$2:$B$200,MATCH(A11,Оборудование!$A$2:$A$200,0)),"") | D11: =IFERROR(INDEX(Оборудование!$C$2:$C$200,MATCH(A11,Оборудование!$A$2:$A$200,0)),"") | E11: =IFERROR(INDEX(Оборудование!$D$2:$D$200,MATCH(A11,Оборудование!$A$2:$A$200,0)),"") | F11: =IFERROR(INDEX(Оборудование!$H$2:$H$200,MATCH(A11,Оборудование!$A$2:$A$200,0)),"") | H11: =IF(G11="","",G11+100) | L11: =IF(K11="","",K11+5) | N11: =IF(M11<>"",M11,IF(L11="","",L11)) | O11: =IF(N11="","",N11+40) | Q11: =IF(P11<>"",P11,IF(O11="","",O11)) | R11: =IF(Q11="","",Q11+70) | T11: =IF(G11="","",IF(S11<>"","Завершено",IF(P11<>"","Ожидание оплаты",IF(M11<>"","Входной контроль",IF(K11<>"","Ожидание получения в Ленске",IF(I11<>"","В пути Иркутск → Ленск","Ремонт у подрядчика")))))) | U11: =IF(H11="","",MAX(0,IF(I11<>"",I11,Настройки!$B$2)-H11)) | V11: =IF(L11="","",MAX(0,IF(M11<>"",M11,Настройки!$B$2)-L11)) | W11: =IF(O11="","",MAX(0,IF(P11<>"",P11,Настройки!$B$2)-O11)) | X11: =IF(R11="","",MAX(0,IF(S11<>"",S11,Настройки!$B$2)-R11)) | Y11: =MAX(U11:X11)
C12: =IFERROR(INDEX(Оборудование!$B$2:$B$200,MATCH(A12,Оборудование!$A$2:$A$200,0)),"") | D12: =IFERROR(INDEX(Оборудование!$C$2:$C$200,MATCH(A12,Оборудование!$A$2:$A$200,0)),"") | E12: =IFERROR(INDEX(Оборудование!$D$2:$D$200,MATCH(A12,Оборудование!$A$2:$A$200,0)),"") | F12: =IFERROR(INDEX(Оборудование!$H$2:$H$200,MATCH(A12,Оборудование!$A$2:$A$200,0)),"") | H12: =IF(G12="","",G12+100) | L12: =IF(K12="","",K12+5) | N12: =IF(M12<>"",M12,IF(L12="","",L12)) | O12: =IF(N12="","",N12+40) | Q12: =IF(P12<>"",P12,IF(O12="","",O12)) | R12: =IF(Q12="","",Q12+70) | T12: =IF(G12="","",IF(S12<>"","Завершено",IF(P12<>"","Ожидание оплаты",IF(M12<>"","Входной контроль",IF(K12<>"","Ожидание получения в Ленске",IF(I12<>"","В пути Иркутск → Ленск","Ремонт у подрядчика")))))) | U12: =IF(H12="","",MAX(0,IF(I12<>"",I12,Настройки!$B$2)-H12)) | V12: =IF(L12="","",MAX(0,IF(M12<>"",M12,Настройки!$B$2)-L12)) | W12: =IF(O12="","",MAX(0,IF(P12<>"",P12,Настройки!$B$2)-O12)) | X12: =IF(R12="","",MAX(0,IF(S12<>"",S12,Настройки!$B$2)-R12)) | Y12: =MAX(U12:X12)
C13: =IFERROR(INDEX(Оборудование!$B$2:$B$200,MATCH(A13,Оборудование!$A$2:$A$200,0)),"") | D13: =IFERROR(INDEX(Оборудование!$C$2:$C$200,MATCH(A13,Оборудование!$A$2:$A$200,0)),"") | E13: =IFERROR(INDEX(Оборудование!$D$2:$D$200,MATCH(A13,Оборудование!$A$2:$A$200,0)),"") | F13: =IFERROR(INDEX(Оборудование!$H$2:$H$200,MATCH(A13,Оборудование!$A$2:$A$200,0)),"") | H13: =IF(G13="","",G13+100) | L13: =IF(K13="","",K13+5) | N13: =IF(M13<>"",M13,IF(L13="","",L13)) | O13: =IF(N13="","",N13+40) | Q13: =IF(P13<>"",P13,IF(O13="","",O13)) | R13: =IF(Q13="","",Q13+70) | T13: =IF(G13="","",IF(S13<>"","Завершено",IF(P13<>"","Ожидание оплаты",IF(M13<>"","Входной контроль",IF(K13<>"","Ожидание получения в Ленске",IF(I13<>"","В пути Иркутск → Ленск","Ремонт у подрядчика")))))) | U13: =IF(H13="","",MAX(0,IF(I13<>"",I13,Настройки!$B$2)-H13)) | V13: =IF(L13="","",MAX(0,IF(M13<>"",M13,Настройки!$B$2)-L13)) | W13: =IF(O13="","",MAX(0,IF(P13<>"",P13,Настройки!$B$2)-O13)) | X13: =IF(R13="","",MAX(0,IF(S13<>"",S13,Настройки!$B$2)-R13)) | Y13: =MAX(U13:X13)
C14: =IFERROR(INDEX(Оборудование!$B$2:$B$200,MATCH(A14,Оборудование!$A$2:$A$200,0)),"") | D14: =IFERROR(INDEX(Оборудование!$C$2:$C$200,MATCH(A14,Оборудование!$A$2:$A$200,0)),"") | E14: =IFERROR(INDEX(Оборудование!$D$2:$D$200,MATCH(A14,Оборудование!$A$2:$A$200,0)),"") | F14: =IFERROR(INDEX(Оборудование!$H$2:$H$200,MATCH(A14,Оборудование!$A$2:$A$200,0)),"") | H14: =IF(G14="","",G14+100) | L14: =IF(K14="","",K14+5) | N14: =IF(M14<>"",M14,IF(L14="","",L14)) | O14: =IF(N14="","",N14+40) | Q14: =IF(P14<>"",P14,IF(O14="","",O14)) | R14: =IF(Q14="","",Q14+70) | T14: =IF(G14="","",IF(S14<>"","Завершено",IF(P14<>"","Ожидание оплаты",IF(M14<>"","Входной контроль",IF(K14<>"","Ожидание получения в Ленске",IF(I14<>"","В пути Иркутск → Ленск","Ремонт у подрядчика")))))) | U14: =IF(H14="","",MAX(0,IF(I14<>"",I14,Настройки!$B$2)-H14)) | V14: =IF(L14="","",MAX(0,IF(M14<>"",M14,Настройки!$B$2)-L14)) | W14: =IF(O14="","",MAX(0,IF(P14<>"",P14,Настройки!$B$2)-O14)) | X14: =IF(R14="","",MAX(0,IF(S14<>"",S14,Настройки!$B$2)-R14)) | Y14: =MAX(U14:X14)
C15: =IFERROR(INDEX(Оборудование!$B$2:$B$200,MATCH(A15,Оборудование!$A$2:$A$200,0)),"") | D15: =IFERROR(INDEX(Оборудование!$C$2:$C$200,MATCH(A15,Оборудование!$A$2:$A$200,0)),"") | E15: =IFERROR(INDEX(Оборудование!$D$2:$D$200,MATCH(A15,Оборудование!$A$2:$A$200,0)),"") | F15: =IFERROR(INDEX(Оборудование!$H$2:$H$200,MATCH(A15,Оборудование!$A$2:$A$200,0)),"") | H15: =IF(G15="","",G15+100) | L15: =IF(K15="","",K15+5) | N15: =IF(M15<>"",M15,IF(L15="","",L15)) | O15: =IF(N15="","",N15+40) | Q15: =IF(P15<>"",P15,IF(O15="","",O15)) | R15: =IF(Q15="","",Q15+70) | T15: =IF(G15="","",IF(S15<>"","Завершено",IF(P15<>"","Ожидание оплаты",IF(M15<>"","Входной контроль",IF(K15<>"","Ожидание получения в Ленске",IF(I15<>"","В пути Иркутск → Ленск","Ремонт у подрядчика")))))) | U15: =IF(H15="","",MAX(0,IF(I15<>"",I15,Настройки!$B$2)-H15)) | V15: =IF(L15="","",MAX(0,IF(M15<>"",M15,Настройки!$B$2)-L15)) | W15: =IF(O15="","",MAX(0,IF(P15<>"",P15,Настройки!$B$2)-O15)) | X15: =IF(R15="","",MAX(0,IF(S15<>"",S15,Настройки!$B$2)-R15)) | Y15: =MAX(U15:X15)
C16: =IFERROR(INDEX(Оборудование!$B$2:$B$200,MATCH(A16,Оборудование!$A$2:$A$200,0)),"") | D16: =IFERROR(INDEX(Оборудование!$C$2:$C$200,MATCH(A16,Оборудование!$A$2:$A$200,0)),"") | E16: =IFERROR(INDEX(Оборудование!$D$2:$D$200,MATCH(A16,Оборудование!$A$2:$A$200,0)),"") | F16: =IFERROR(INDEX(Оборудование!$H$2:$H$200,MATCH(A16,Оборудование!$A$2:$A$200,0)),"") | H16: =IF(G16="","",G16+100) | L16: =IF(K16="","",K16+5) | N16: =IF(M16<>"",M16,IF(L16="","",L16)) | O16: =IF(N16="","",N16+40) | Q16: =IF(P16<>"",P16,IF(O16="","",O16)) | R16: =IF(Q16="","",Q16+70) | T16: =IF(G16="","",IF(S16<>"","Завершено",IF(P16<>"","Ожидание оплаты",IF(M16<>"","Входной контроль",IF(K16<>"","Ожидание получения в Ленске",IF(I16<>"","В пути Иркутск → Ленск","Ремонт у подрядчика")))))) | U16: =IF(H16="","",MAX(0,IF(I16<>"",I16,Настройки!$B$2)-H16)) | V16: =IF(L16="","",MAX(0,IF(M16<>"",M16,Настройки!$B$2)-L16)) | W16: =IF(O16="","",MAX(0,IF(P16<>"",P16,Настройки!$B$2)-O16)) | X16: =IF(R16="","",MAX(0,IF(S16<>"",S16,Настройки!$B$2)-R16)) | Y16: =MAX(U16:X16)
C17: =IFERROR(INDEX(Оборудование!$B$2:$B$200,MATCH(A17,Оборудование!$A$2:$A$200,0)),"") | D17: =IFERROR(INDEX(Оборудование!$C$2:$C$200,MATCH(A17,Оборудование!$A$2:$A$200,0)),"") | E17: =IFERROR(INDEX(Оборудование!$D$2:$D$200,MATCH(A17,Оборудование!$A$2:$A$200,0)),"") | F17: =IFERROR(INDEX(Оборудование!$H$2:$H$200,MATCH(A17,Оборудование!$A$2:$A$200,0)),"") | H17: =IF(G17="","",G17+100) | L17: =IF(K17="","",K17+5) | N17: =IF(M17<>"",M17,IF(L17="","",L17)) | O17: =IF(N17="","",N17+40) | Q17: =IF(P17<>"",P17,IF(O17="","",O17)) | R17: =IF(Q17="","",Q17+70) | T17: =IF(G17="","",IF(S17<>"","Завершено",IF(P17<>"","Ожидание оплаты",IF(M17<>"","Входной контроль",IF(K17<>"","Ожидание получения в Ленске",IF(I17<>"","В пути Иркутск → Ленск","Ремонт у подрядчика")))))) | U17: =IF(H17="","",MAX(0,IF(I17<>"",I17,Настройки!$B$2)-H17)) | V17: =IF(L17="","",MAX(0,IF(M17<>"",M17,Настройки!$B$2)-L17)) | W17: =IF(O17="","",MAX(0,IF(P17<>"",P17,Настройки!$B$2)-O17)) | X17: =IF(R17="","",MAX(0,IF(S17<>"",S17,Настройки!$B$2)-R17)) | Y17: =MAX(U17:X17)
C18: =IFERROR(INDEX(Оборудование!$B$2:$B$200,MATCH(A18,Оборудование!$A$2:$A$200,0)),"") | D18: =IFERROR(INDEX(Оборудование!$C$2:$C$200,MATCH(A18,Оборудование!$A$2:$A$200,0)),"") | E18: =IFERROR(INDEX(Оборудование!$D$2:$D$200,MATCH(A18,Оборудование!$A$2:$A$200,0)),"") | F18: =IFERROR(INDEX(Оборудование!$H$2:$H$200,MATCH(A18,Оборудование!$A$2:$A$200,0)),"") | H18: =IF(G18="","",G18+100) | L18: =IF(K18="","",K18+5) | N18: =IF(M18<>"",M18,IF(L18="","",L18)) | O18: =IF(N18="","",N18+40) | Q18: =IF(P18<>"",P18,IF(O18="","",O18)) | R18: =IF(Q18="","",Q18+70) | T18: =IF(G18="","",IF(S18<>"","Завершено",IF(P18<>"","Ожидание оплаты",IF(M18<>"","Входной контроль",IF(K18<>"","Ожидание получения в Ленске",IF(I18<>"","В пути Иркутск → Ленск","Ремонт у подрядчика")))))) | U18: =IF(H18="","",MAX(0,IF(I18<>"",I18,Настройки!$B$2)-H18)) | V18: =IF(L18="","",MAX(0,IF(M18<>"",M18,Настройки!$B$2)-L18)) | W18: =IF(O18="","",MAX(0,IF(P18<>"",P18,Настройки!$B$2)-O18)) | X18: =IF(R18="","",MAX(0,IF(S18<>"",S18,Настройки!$B$2)-R18)) | Y18: =MAX(U18:X18)
C19: =IFERROR(INDEX(Оборудование!$B$2:$B$200,MATCH(A19,Оборудование!$A$2:$A$200,0)),"") | D19: =IFERROR(INDEX(Оборудование!$C$2:$C$200,MATCH(A19,Оборудование!$A$2:$A$200,0)),"") | E19: =IFERROR(INDEX(Оборудование!$D$2:$D$200,MATCH(A19,Оборудование!$A$2:$A$200,0)),"") | F19: =IFERROR(INDEX(Оборудование!$H$2:$H$200,MATCH(A19,Оборудование!$A$2:$A$200,0)),"") | H19: =IF(G19="","",G19+100) | L19: =IF(K19="","",K19+5) | N19: =IF(M19<>"",M19,IF(L19="","",L19)) | O19: =IF(N19="","",N19+40) | Q19: =IF(P19<>"",P19,IF(O19="","",O19)) | R19: =IF(Q19="","",Q19+70) | T19: =IF(G19="","",IF(S19<>"","Завершено",IF(P19<>"","Ожидание оплаты",IF(M19<>"","Входной контроль",IF(K19<>"","Ожидание получения в Ленске",IF(I19<>"","В пути Иркутск → Ленск","Ремонт у подрядчика")))))) | U19: =IF(H19="","",MAX(0,IF(I19<>"",I19,Настройки!$B$2)-H19)) | V19: =IF(L19="","",MAX(0,IF(M19<>"",M19,Настройки!$B$2)-L19)) | W19: =IF(O19="","",MAX(0,IF(P19<>"",P19,Настройки!$B$2)-O19)) | X19: =IF(R19="","",MAX(0,IF(S19<>"",S19,Настройки!$B$2)-R19)) | Y19: =MAX(U19:X19)
... C200: =IFERROR(INDEX(Оборудование!$B$2:$B$200,MATCH(A200,Оборудование!$A$2:$A$200,0)),"") | D200: =IFERROR(INDEX(Оборудование!$C$2:$C$200,MATCH(A200,Оборудование!$A$2:$A$200,0)),"") | E200: =IFERROR(INDEX(Оборудование!$D$2:$D$200,MATCH(A200,Оборудование!$A$2:$A$200,0)),"") | F200: =IFERROR(INDEX(Оборудование!$H$2:$H$200,MATCH(A200,Оборудование!$A$2:$A$200,0)),"") | H200: =IF(G200="","",G200+100) | L200: =IF(K200="","",K200+5) | N200: =IF(M200<>"",M200,IF(L200="","",L200)) | O200: =IF(N200="","",N200+40) | Q200: =IF(P200<>"",P200,IF(O200="","",O200)) | R200: =IF(Q200="","",Q200+70) | T200: =IF(G200="","",IF(S200<>"","Завершено",IF(P200<>"","Ожидание оплаты",IF(M200<>"","Входной контроль",IF(K200<>"","Ожидание получения в Ленске",IF(I200<>"","В пути Иркутск → Ленск","Ремонт у подрядчика")))))) | U200: =IF(H200="","",MAX(0,IF(I200<>"",I200,Настройки!$B$2)-H200)) | V200: =IF(L200="","",MAX(0,IF(M200<>"",M200,Настройки!$B$2)-L200)) | W200: =IF(O200="","",MAX(0,IF(P200<>"",P200,Настройки!$B$2)-O200)) | X200: =IF(R200="","",MAX(0,IF(S200<>"",S200,Настройки!$B$2)-R200)) | Y200: =MAX(U200:X200)

Sheet Журнал_событий
A1: Дата события | B1: ID прибора | C1: Тип | D1: Наименование | E1: Событие | F1: Текущий этап | G1: Комментарий
A2: =IF(Ремонты!G2="","",Ремонты!G2) | B2: =IF($A2="","",Ремонты!A2) | C2: =IF($A2="","",Ремонты!D2) | D2: =IF($A2="","",Ремонты!E2) | E2: =IF($A2="","","Отправка в ремонт") | F2: =IF($A2="","",Ремонты!T2) | G2: =IF($A2="","","Автозапись из листа Ремонты")
A3: =IF(Ремонты!I2="","",Ремонты!I2) | B3: =IF($A3="","",Ремонты!A2) | C3: =IF($A3="","",Ремонты!D2) | D3: =IF($A3="","",Ремонты!E2) | E3: =IF($A3="","","Отправка из ремонта") | F3: =IF($A3="","",Ремонты!T2) | G3: =IF($A3="","","Автозапись из листа Ремонты")
A4: =IF(Ремонты!J2="","",Ремонты!J2) | B4: =IF($A4="","",Ремонты!A2) | C4: =IF($A4="","",Ремонты!D2) | D4: =IF($A4="","",Ремонты!E2) | E4: =IF($A4="","","Отправка из Иркутска") | F4: =IF($A4="","",Ремонты!T2) | G4: =IF($A4="","","Автозапись из листа Ремонты")
A5: =IF(Ремонты!K2="","",Ремонты!K2) | B5: =IF($A5="","",Ремонты!A2) | C5: =IF($A5="","",Ремонты!D2) | D5: =IF($A5="","",Ремонты!E2) | E5: =IF($A5="","","Прибытие в Ленск") | F5: =IF($A5="","",Ремонты!T2) | G5: =IF($A5="","","Автозапись из листа Ремонты")
A6: =IF(Ремонты!M2="","",Ремонты!M2) | B6: =IF($A6="","",Ремонты!A2) | C6: =IF($A6="","",Ремонты!D2) | D6: =IF($A6="","",Ремонты!E2) | E6: =IF($A6="","","Фактическое получение") | F6: =IF($A6="","",Ремонты!T2) | G6: =IF($A6="","","Автозапись из листа Ремонты")
A7: =IF(Ремонты!P2="","",Ремонты!P2) | B7: =IF($A7="","",Ремонты!A2) | C7: =IF($A7="","",Ремонты!D2) | D7: =IF($A7="","",Ремонты!E2) | E7: =IF($A7="","","Входной контроль") | F7: =IF($A7="","",Ремонты!T2) | G7: =IF($A7="","","Автозапись из листа Ремонты")
A8: =IF(Ремонты!S2="","",Ремонты!S2) | B8: =IF($A8="","",Ремонты!A2) | C8: =IF($A8="","",Ремонты!D2) | D8: =IF($A8="","",Ремонты!E2) | E8: =IF($A8="","","Оплата") | F8: =IF($A8="","",Ремонты!T2) | G8: =IF($A8="","","Автозапись из листа Ремонты")
A9: =IF(Ремонты!G3="","",Ремонты!G3) | B9: =IF($A9="","",Ремонты!A3) | C9: =IF($A9="","",Ремонты!D3) | D9: =IF($A9="","",Ремонты!E3) | E9: =IF($A9="","","Отправка в ремонт") | F9: =IF($A9="","",Ремонты!T3) | G9: =IF($A9="","","Автозапись из листа Ремонты")
A10: =IF(Ремонты!I3="","",Ремонты!I3) | B10: =IF($A10="","",Ремонты!A3) | C10: =IF($A10="","",Ремонты!D3) | D10: =IF($A10="","",Ремонты!E3) | E10: =IF($A10="","","Отправка из ремонта") | F10: =IF($A10="","",Ремонты!T3) | G10: =IF($A10="","","Автозапись из листа Ремонты")
A11: =IF(Ремонты!J3="","",Ремонты!J3) | B11: =IF($A11="","",Ремонты!A3) | C11: =IF($A11="","",Ремонты!D3) | D11: =IF($A11="","",Ремонты!E3) | E11: =IF($A11="","","Отправка из Иркутска") | F11: =IF($A11="","",Ремонты!T3) | G11: =IF($A11="","","Автозапись из листа Ремонты")
A12: =IF(Ремонты!K3="","",Ремонты!K3) | B12: =IF($A12="","",Ремонты!A3) | C12: =IF($A12="","",Ремонты!D3) | D12: =IF($A12="","",Ремонты!E3) | E12: =IF($A12="","","Прибытие в Ленск") | F12: =IF($A12="","",Ремонты!T3) | G12: =IF($A12="","","Автозапись из листа Ремонты")
A13: =IF(Ремонты!M3="","",Ремонты!M3) | B13: =IF($A13="","",Ремонты!A3) | C13: =IF($A13="","",Ремонты!D3) | D13: =IF($A13="","",Ремонты!E3) | E13: =IF($A13="","","Фактическое получение") | F13: =IF($A13="","",Ремонты!T3) | G13: =IF($A13="","","Автозапись из листа Ремонты")
A14: =IF(Ремонты!P3="","",Ремонты!P3) | B14: =IF($A14="","",Ремонты!A3) | C14: =IF($A14="","",Ремонты!D3) | D14: =IF($A14="","",Ремонты!E3) | E14: =IF($A14="","","Входной контроль") | F14: =IF($A14="","",Ремонты!T3) | G14: =IF($A14="","","Автозапись из листа Ремонты")
A15: =IF(Ремонты!S3="","",Ремонты!S3) | B15: =IF($A15="","",Ремонты!A3) | C15: =IF($A15="","",Ремонты!D3) | D15: =IF($A15="","",Ремонты!E3) | E15: =IF($A15="","","Оплата") | F15: =IF($A15="","",Ремонты!T3) | G15: =IF($A15="","","Автозапись из листа Ремонты")
A16: =IF(Ремонты!G4="","",Ремонты!G4) | B16: =IF($A16="","",Ремонты!A4) | C16: =IF($A16="","",Ремонты!D4) | D16: =IF($A16="","",Ремонты!E4) | E16: =IF($A16="","","Отправка в ремонт") | F16: =IF($A16="","",Ремонты!T4) | G16: =IF($A16="","","Автозапись из листа Ремонты")
A17: =IF(Ремонты!I4="","",Ремонты!I4) | B17: =IF($A17="","",Ремонты!A4) | C17: =IF($A17="","",Ремонты!D4) | D17: =IF($A17="","",Ремонты!E4) | E17: =IF($A17="","","Отправка из ремонта") | F17: =IF($A17="","",Ремонты!T4) | G17: =IF($A17="","","Автозапись из листа Ремонты")
A18: =IF(Ремонты!J4="","",Ремонты!J4) | B18: =IF($A18="","",Ремонты!A4) | C18: =IF($A18="","",Ремонты!D4) | D18: =IF($A18="","",Ремонты!E4) | E18: =IF($A18="","","Отправка из Иркутска") | F18: =IF($A18="","",Ремонты!T4) | G18: =IF($A18="","","Автозапись из листа Ремонты")
A19: =IF(Ремонты!K4="","",Ремонты!K4) | B19: =IF($A19="","",Ремонты!A4) | C19: =IF($A19="","",Ремонты!D4) | D19: =IF($A19="","",Ремонты!E4) | E19: =IF($A19="","","Прибытие в Ленск") | F19: =IF($A19="","",Ремонты!T4) | G19: =IF($A19="","","Автозапись из листа Ремонты")
A20: =IF(Ремонты!M4="","",Ремонты!M4) | B20: =IF($A20="","",Ремонты!A4) | C20: =IF($A20="","",Ремонты!D4) | D20: =IF($A20="","",Ремонты!E4) | E20: =IF($A20="","","Фактическое получение") | F20: =IF($A20="","",Ремонты!T4) | G20: =IF($A20="","","Автозапись из листа Ремонты")
A21: =IF(Ремонты!P4="","",Ремонты!P4) | B21: =IF($A21="","",Ремонты!A4) | C21: =IF($A21="","",Ремонты!D4) | D21: =IF($A21="","",Ремонты!E4) | E21: =IF($A21="","","Входной контроль") | F21: =IF($A21="","",Ремонты!T4) | G21: =IF($A21="","","Автозапись из листа Ремонты")
A22: =IF(Ремонты!S4="","",Ремонты!S4) | B22: =IF($A22="","",Ремонты!A4) | C22: =IF($A22="","",Ремонты!D4) | D22: =IF($A22="","",Ремонты!E4) | E22: =IF($A22="","","Оплата") | F22: =IF($A22="","",Ремонты!T4) | G22: =IF($A22="","","Автозапись из листа Ремонты")
A23: =IF(Ремонты!G5="","",Ремонты!G5) | B23: =IF($A23="","",Ремонты!A5) | C23: =IF($A23="","",Ремонты!D5) | D23: =IF($A23="","",Ремонты!E5) | E23: =IF($A23="","","Отправка в ремонт") | F23: =IF($A23="","",Ремонты!T5) | G23: =IF($A23="","","Автозапись из листа Ремонты")
A24: =IF(Ремонты!I5="","",Ремонты!I5) | B24: =IF($A24="","",Ремонты!A5) | C24: =IF($A24="","",Ремонты!D5) | D24: =IF($A24="","",Ремонты!E5) | E24: =IF($A24="","","Отправка из ремонта") | F24: =IF($A24="","",Ремонты!T5) | G24: =IF($A24="","","Автозапись из листа Ремонты")
A25: =IF(Ремонты!J5="","",Ремонты!J5) | B25: =IF($A25="","",Ремонты!A5) | C25: =IF($A25="","",Ремонты!D5) | D25: =IF($A25="","",Ремонты!E5) | E25: =IF($A25="","","Отправка из Иркутска") | F25: =IF($A25="","",Ремонты!T5) | G25: =IF($A25="","","Автозапись из листа Ремонты")
A26: =IF(Ремонты!K5="","",Ремонты!K5) | B26: =IF($A26="","",Ремонты!A5) | C26: =IF($A26="","",Ремонты!D5) | D26: =IF($A26="","",Ремонты!E5) | E26: =IF($A26="","","Прибытие в Ленск") | F26: =IF($A26="","",Ремонты!T5) | G26: =IF($A26="","","Автозапись из листа Ремонты")
A27: =IF(Ремонты!M5="","",Ремонты!M5) | B27: =IF($A27="","",Ремонты!A5) | C27: =IF($A27="","",Ремонты!D5) | D27: =IF($A27="","",Ремонты!E5) | E27: =IF($A27="","","Фактическое получение") | F27: =IF($A27="","",Ремонты!T5) | G27: =IF($A27="","","Автозапись из листа Ремонты")
A28: =IF(Ремонты!P5="","",Ремонты!P5) | B28: =IF($A28="","",Ремонты!A5) | C28: =IF($A28="","",Ремонты!D5) | D28: =IF($A28="","",Ремонты!E5) | E28: =IF($A28="","","Входной контроль") | F28: =IF($A28="","",Ремонты!T5) | G28: =IF($A28="","","Автозапись из листа Ремонты")
A29: =IF(Ремонты!S5="","",Ремонты!S5) | B29: =IF($A29="","",Ремонты!A5) | C29: =IF($A29="","",Ремонты!D5) | D29: =IF($A29="","",Ремонты!E5) | E29: =IF($A29="","","Оплата") | F29: =IF($A29="","",Ремонты!T5) | G29: =IF($A29="","","Автозапись из листа Ремонты")
A30: =IF(Ремонты!G6="","",Ремонты!G6) | B30: =IF($A30="","",Ремонты!A6) | C30: =IF($A30="","",Ремонты!D6) | D30: =IF($A30="","",Ремонты!E6) | E30: =IF($A30="","","Отправка в ремонт") | F30: =IF($A30="","",Ремонты!T6) | G30: =IF($A30="","","Автозапись из листа Ремонты")
A31: =IF(Ремонты!I6="","",Ремонты!I6) | B31: =IF($A31="","",Ремонты!A6) | C31: =IF($A31="","",Ремонты!D6) | D31: =IF($A31="","",Ремонты!E6) | E31: =IF($A31="","","Отправка из ремонта") | F31: =IF($A31="","",Ремонты!T6) | G31: =IF($A31="","","Автозапись из листа Ремонты")
A32: =IF(Ремонты!J6="","",Ремонты!J6) | B32: =IF($A32="","",Ремонты!A6) | C32: =IF($A32="","",Ремонты!D6) | D32: =IF($A32="","",Ремонты!E6) | E32: =IF($A32="","","Отправка из Иркутска") | F32: =IF($A32="","",Ремонты!T6) | G32: =IF($A32="","","Автозапись из листа Ремонты")
A33: =IF(Ремонты!K6="","",Ремонты!K6) | B33: =IF($A33="","",Ремонты!A6) | C33: =IF($A33="","",Ремонты!D6) | D33: =IF($A33="","",Ремонты!E6) | E33: =IF($A33="","","Прибытие в Ленск") | F33: =IF($A33="","",Ремонты!T6) | G33: =IF($A33="","","Автозапись из листа Ремонты")
A34: =IF(Ремонты!M6="","",Ремонты!M6) | B34: =IF($A34="","",Ремонты!A6) | C34: =IF($A34="","",Ремонты!D6) | D34: =IF($A34="","",Ремонты!E6) | E34: =IF($A34="","","Фактическое получение") | F34: =IF($A34="","",Ремонты!T6) | G34: =IF($A34="","","Автозапись из листа Ремонты")
A35: =IF(Ремонты!P6="","",Ремонты!P6) | B35: =IF($A35="","",Ремонты!A6) | C35: =IF($A35="","",Ремонты!D6) | D35: =IF($A35="","",Ремонты!E6) | E35: =IF($A35="","","Входной контроль") | F35: =IF($A35="","",Ремонты!T6) | G35: =IF($A35="","","Автозапись из листа Ремонты")
A36: =IF(Ремонты!S6="","",Ремонты!S6) | B36: =IF($A36="","",Ремонты!A6) | C36: =IF($A36="","",Ремонты!D6) | D36: =IF($A36="","",Ремонты!E6) | E36: =IF($A36="","","Оплата") | F36: =IF($A36="","",Ремонты!T6) | G36: =IF($A36="","","Автозапись из листа Ремонты")
A37: =IF(Ремонты!G7="","",Ремонты!G7) | B37: =IF($A37="","",Ремонты!A7) | C37: =IF($A37="","",Ремонты!D7) | D37: =IF($A37="","",Ремонты!E7) | E37: =IF($A37="","","Отправка в ремонт") | F37: =IF($A37="","",Ремонты!T7) | G37: =IF($A37="","","Автозапись из листа Ремонты")
A38: =IF(Ремонты!I7="","",Ремонты!I7) | B38: =IF($A38="","",Ремонты!A7) | C38: =IF($A38="","",Ремонты!D7) | D38: =IF($A38="","",Ремонты!E7) | E38: =IF($A38="","","Отправка из ремонта") | F38: =IF($A38="","",Ремонты!T7) | G38: =IF($A38="","","Автозапись из листа Ремонты")
A39: =IF(Ремонты!J7="","",Ремонты!J7) | B39: =IF($A39="","",Ремонты!A7) | C39: =IF($A39="","",Ремонты!D7) | D39: =IF($A39="","",Ремонты!E7) | E39: =IF($A39="","","Отправка из Иркутска") | F39: =IF($A39="","",Ремонты!T7) | G39: =IF($A39="","","Автозапись из листа Ремонты")
A40: =IF(Ремонты!K7="","",Ремонты!K7) | B40: =IF($A40="","",Ремонты!A7) | C40: =IF($A40="","",Ремонты!D7) | D40: =IF($A40="","",Ремонты!E7) | E40: =IF($A40="","","Прибытие в Ленск") | F40: =IF($A40="","",Ремонты!T7) | G40: =IF($A40="","","Автозапись из листа Ремонты")
...

Sheet Карточка_прибора
A1: КАРТОЧКА ПРИБОРА
A4: Выберите ID | B4: SI-0001
A6: ID прибора | B6: =IFERROR(INDEX(Оборудование!$A$2:$A$200,MATCH($B$4,Оборудование!$A$2:$A$200,0)),"") | D6: Рег. номер типа СИ | E6: =IF(B8="СИ",IFERROR(INDEX(Оборудование!$K$2:$K$200,MATCH($B$4,Оборудование!$A$2:$A$200,0)),""),"не применяется")
A7: Объект | B7: =IFERROR(INDEX(Оборудование!$B$2:$B$200,MATCH($B$4,Оборудование!$A$2:$A$200,0)),"") | D7: Наименование типа СИ | E7: =IF(B8="СИ",IFERROR(INDEX(Оборудование!$L$2:$L$200,MATCH($B$4,Оборудование!$A$2:$A$200,0)),""),"не применяется")
A8: Тип | B8: =IFERROR(INDEX(Оборудование!$C$2:$C$200,MATCH($B$4,Оборудование!$A$2:$A$200,0)),"") | D8: Обозначение типа СИ | E8: =IF(B8="СИ",IFERROR(INDEX(Оборудование!$M$2:$M$200,MATCH($B$4,Оборудование!$A$2:$A$200,0)),""),"не применяется")
A9: Наименование | B9: =IFERROR(INDEX(Оборудование!$D$2:$D$200,MATCH($B$4,Оборудование!$A$2:$A$200,0)),"") | D9: Номер свидетельства | E9: =IF(B8="СИ",IFERROR(INDEX(Оборудование!$N$2:$N$200,MATCH($B$4,Оборудование!$A$2:$A$200,0)),""),"не применяется")
A10: Модификация | B10: =IFERROR(INDEX(Оборудование!$E$2:$E$200,MATCH($B$4,Оборудование!$A$2:$A$200,0)),"") | D10: Дата поверки | E10: =IF(B8="СИ",IFERROR(INDEX(Оборудование!$O$2:$O$200,MATCH($B$4,Оборудование!$A$2:$A$200,0)),""),"не применяется")
A11: Заводской номер | B11: =IFERROR(INDEX(Оборудование!$F$2:$F$200,MATCH($B$4,Оборудование!$A$2:$A$200,0)),"") | D11: Поверка до | E11: =IF(B8="СИ",IFERROR(INDEX(Оборудование!$P$2:$P$200,MATCH($B$4,Оборудование!$A$2:$A$200,0)),""),"не применяется")
A12: Статус | B12: =IFERROR(INDEX(Оборудование!$H$2:$H$200,MATCH($B$4,Оборудование!$A$2:$A$200,0)),"") | D12: Владелец СИ | E12: =IF(B8="СИ",IFERROR(INDEX(Оборудование!$Q$2:$Q$200,MATCH($B$4,Оборудование!$A$2:$A$200,0)),""),"не применяется")
A13: Где сейчас прибор | B13: =IFERROR(INDEX(Оборудование!$I$2:$I$200,MATCH($B$4,Оборудование!$A$2:$A$200,0)),"") | D13: Этап ремонта | E13: =IFERROR(INDEX(Ремонты!$T$2:$T$200,MATCH($B$4,Ремонты!$A$2:$A$200,0)),"нет активного ремонта")
A14: Активный ремонт | B14: =IFERROR(INDEX(Оборудование!$J$2:$J$200,MATCH($B$4,Оборудование!$A$2:$A$200,0)),"") | D14: Макс. просрочка | E14: =IFERROR(INDEX(Ремонты!$Y$2:$Y$200,MATCH($B$4,Ремонты!$A$2:$A$200,0)),"-")
A16: Подсказка | B16: Для ИО, ВО и Другое поля СИ автоматически показывают «не применяется».

Sheet Как_пользоваться
A1: Что добавлено | B1: Карточка прибора, автостатус «где сейчас прибор», тестовые ВО/ИО/Другое и автожурнал событий.
A2: Как работает журнал | B2: Если вы меняете дату на листе Ремонты, связанная запись автоматически появляется или меняется в листе Журнал_событий.
A3: Что важно | B3: Это именно автожурнал событий по введенным датам, а не неоткатный аудит изменений. Для настоящего журнала правок нужен VBA или база данных.
A4: Связи | B4: Лист Ремонты подтягивает объект, тип, наименование и статус прибора по ID из листа Оборудование.
A5: Тест | B5: Контрольная дата для теста сейчас 11.03.2026 на листе Настройки.
